husarion@~/Desktop$ ros2 param get /robot_state_publisher robot_description
String value is: <?xml version="1.0" ?> <!-- =================================================================================== --> <!-- |    This document was autogenerated by xacro from /snap/rosbot/42/opt/ros/snap/share/rosbot_description/urdf/rosbot.urdf.xacro | --> <!-- |    EDITING THIS FILE BY HAND IS NOT RECOMMENDED                                 | --> <!-- =================================================================================== --> <robot name="rosbot"> <link name="base_link"/> <joint name="base_to_body_joint" type="fixed"> <origin rpy="0.0 0.0 0.0" xyz="0.0 0.0 0.0425"/> <parent link="base_link"/> <child link="body_link"/> </joint> <link name="body_link"> <visual> <geometry> <mesh filename="package://rosbot_description/meshes/body.stl" scale="0.001 0.001 0.001"/> </geometry> <origin rpy="1.5707963267948966 0.0 1.5707963267948966" xyz="0.0 0.0 -0.0173"/> <material name="White"> <color rgba="1.0 1.0 1.0 1.0"/> </material> </visual> <collision> <geometry> <box size="0.197 0.150 0.080"/> </geometry> <origin rpy="0.0 0.0 0.0" xyz="0.0 0.0 0.02"/> </collision> <inertial> <mass value="1.728"/> <inertia ixx="0.004162" ixy="0.0" ixz="0.0" iyy="0.00651" iyz="0.0" izz="0.008828"/> <origin rpy="0.0 0.0 0.0" xyz="0.0 0.0 0.02"/> </inertial> </link> <gazebo reference="body_link"> <material>Gazebo/White</material> </gazebo> <joint name="body_to_cover_joint" type="fixed"> <origin rpy="0.0 0.0 0.0" xyz="0.0 0.0 0.0603"/> <parent link="body_link"/> <child link="cover_link"/> </joint> <link name="cover_link"> <visual> <geometry> <mesh filename="package://rosbot_description/meshes/cover.stl" scale="0.001 0.001 0.001"/> </geometry> <origin rpy="1.5707963267948966 0.0 1.5707963267948966" xyz="0.0 0.0 -0.002"/> <material name="Red"> <color rgba="0.8 0.0 0.0 1.0"/> </material> </visual> <gazebo reference="cover_link"> <material>Gazebo/Red</material> </gazebo> </link> <joint name="body_to_imu_joint" type="fixed"> <origin rpy="0.0 0.0 0.0" xyz="0.003 -0.0495 0.04332"/> <parent link="body_link"/> <child link="imu_link"/> </joint> <link name="imu_link"/> <joint name="body_to_camera_joint" type="fixed"> <origin rpy="0.0 0.0 0.0" xyz="-0.0141 0.0 0.125"/> <parent link="body_link"/> <child link="camera_link"/> </joint> <link name="camera_link"/> <joint name="body_link_fl_range_joint" type="fixed"> <origin rpy="0.0 0.0 0.2181661564992912" xyz="0.0926  0.05 0.015"/> <parent link="body_link"/> <child link="fl_range"/> </joint> <link name="fl_range"/> <gazebo reference="fl_range"> <sensor name="fl_range" type="gpu_lidar"> <topic>range/fl</topic> <frame_id>fl_range</frame_id> <ignition_frame_id>fl_range</ignition_frame_id> <update_rate>5.0</update_rate> <ray> <scan> <horizontal> <samples>1</samples> <resolution>1</resolution> <min_angle>-0.01</min_angle> <max_angle>0.01</max_angle> </horizontal> </scan> <range> <min>0.01</min> <max>0.90</max> <resolution>0.02</resolution> </range> <noise> <type>gaussian</type> <mean>0.1</mean> <stddev>0.005</stddev> </noise> </ray> <always_on>true</always_on> <visualize>false</visualize> <ros> <namespace></namespace> </ros> </sensor> </gazebo> <joint name="body_link_fr_range_joint" type="fixed"> <origin rpy="0.0 0.0 -0.2181661564992912" xyz="0.0926 -0.05 0.015"/> <parent link="body_link"/> <child link="fr_range"/> </joint> <link name="fr_range"/> <gazebo reference="fr_range"> <sensor name="fr_range" type="gpu_lidar"> <topic>range/fr</topic> <frame_id>fr_range</frame_id> <ignition_frame_id>fr_range</ignition_frame_id> <update_rate>5.0</update_rate> <ray> <scan> <horizontal> <samples>1</samples> <resolution>1</resolution> <min_angle>-0.01</min_angle> <max_angle>0.01</max_angle> </horizontal> </scan> <range> <min>0.01</min> <max>0.90</max> <resolution>0.02</resolution> </range> <noise> <type>gaussian</type> <mean>0.1</mean> <stddev>0.005</stddev> </noise> </ray> <always_on>true</always_on> <visualize>false</visualize> <ros> <namespace></namespace> </ros> </sensor> </gazebo> <joint name="body_link_rl_range_joint" type="fixed"> <origin rpy="0.0 0.0 2.923426497090502" xyz="-0.0926 0.05 0.0115"/> <parent link="body_link"/> <child link="rl_range"/> </joint> <link name="rl_range"/> <gazebo reference="rl_range"> <sensor name="rl_range" type="gpu_lidar"> <topic>range/rl</topic> <frame_id>rl_range</frame_id> <ignition_frame_id>rl_range</ignition_frame_id> <update_rate>5.0</update_rate> <ray> <scan> <horizontal> <samples>1</samples> <resolution>1</resolution> <min_angle>-0.01</min_angle> <max_angle>0.01</max_angle> </horizontal> </scan> <range> <min>0.01</min> <max>0.90</max> <resolution>0.02</resolution> </range> <noise> <type>gaussian</type> <mean>0.1</mean> <stddev>0.005</stddev> </noise> </ray> <always_on>true</always_on> <visualize>false</visualize> <ros> <namespace></namespace> </ros> </sensor> </gazebo> <joint name="body_link_rr_range_joint" type="fixed"> <origin rpy="0.0 0.0 3.3597588100890845" xyz="-0.0926 -0.05 0.0115"/> <parent link="body_link"/> <child link="rr_range"/> </joint> <link name="rr_range"/> <gazebo reference="rr_range"> <sensor name="rr_range" type="gpu_lidar"> <topic>range/rr</topic> <frame_id>rr_range</frame_id> <ignition_frame_id>rr_range</ignition_frame_id> <update_rate>5.0</update_rate> <ray> <scan> <horizontal> <samples>1</samples> <resolution>1</resolution> <min_angle>-0.01</min_angle> <max_angle>0.01</max_angle> </horizontal> </scan> <range> <min>0.01</min> <max>0.90</max> <resolution>0.02</resolution> </range> <noise> <type>gaussian</type> <mean>0.1</mean> <stddev>0.005</stddev> </noise> </ray> <always_on>true</always_on> <visualize>false</visualize> <ros> <namespace></namespace> </ros> </sensor> </gazebo> <joint name="fr_wheel_joint" type="continuous"> <parent link="body_link"/> <child link="fr_wheel_link"/> <origin rpy="0.0 0.0 0.0" xyz="0.053 -0.096 0.0"/> <axis xyz="0.0 1.0 0.0"/> <limit effort="1.5" velocity="24.0"/> <dynamics damping="0.001" friction="0.001"/> </joint> <link name="fr_wheel_link"> <visual> <geometry> <mesh filename="package://rosbot_description/meshes/wheel_a.dae" scale="1.0 1.0 1.0"/> </geometry> <origin rpy="0.0 0.0 3.141592653589793" xyz="0.0 0.0 0.0"/> </visual> <collision> <geometry> <cylinder length="0.036" radius="0.0425"/> </geometry> <origin rpy="1.5707963267948966 0.0 0.0" xyz="0.0 0.0 0.0"/> </collision> <inertial> <mass value="0.074"/> <inertia ixx="4.1e-05" ixy="0.0" ixz="0.0" iyy="6.7e-05" iyz="0.0" izz="4.1e-05"/> </inertial> </link> <joint name="fl_wheel_joint" type="continuous"> <parent link="body_link"/> <child link="fl_wheel_link"/> <origin rpy="0.0 0.0 0.0" xyz="0.053 0.096 0.0"/> <axis xyz="0.0 1.0 0.0"/> <limit effort="1.5" velocity="24.0"/> <dynamics damping="0.001" friction="0.001"/> </joint> <link name="fl_wheel_link"> <visual> <geometry> <mesh filename="package://rosbot_description/meshes/wheel_b.dae" scale="1.0 1.0 1.0"/> </geometry> <origin rpy="0.0 0.0 3.141592653589793" xyz="0.0 0.0 0.0"/> </visual> <collision> <geometry> <cylinder length="0.036" radius="0.0425"/> </geometry> <origin rpy="1.5707963267948966 0.0 0.0" xyz="0.0 0.0 0.0"/> </collision> <inertial> <mass value="0.074"/> <inertia ixx="4.1e-05" ixy="0.0" ixz="0.0" iyy="6.7e-05" iyz="0.0" izz="4.1e-05"/> </inertial> </link> <joint name="rl_wheel_joint" type="continuous"> <parent link="body_link"/> <child link="rl_wheel_link"/> <origin rpy="0.0 0.0 0.0" xyz="-0.053 0.096 0.0"/> <axis xyz="0.0 1.0 0.0"/> <limit effort="1.5" velocity="24.0"/> <dynamics damping="0.001" friction="0.001"/> </joint> <link name="rl_wheel_link"> <visual> <geometry> <mesh filename="package://rosbot_description/meshes/wheel_a.dae" scale="1.0 1.0 1.0"/> </geometry> <origin rpy="0.0 0.0 0.0" xyz="0.0 0.0 0.0"/> </visual> <collision> <geometry> <cylinder length="0.036" radius="0.0425"/> </geometry> <origin rpy="1.5707963267948966 0.0 0.0" xyz="0.0 0.0 0.0"/> </collision> <inertial> <mass value="0.074"/> <inertia ixx="4.1e-05" ixy="0.0" ixz="0.0" iyy="6.7e-05" iyz="0.0" izz="4.1e-05"/> </inertial> </link> <joint name="rr_wheel_joint" type="continuous"> <parent link="body_link"/> <child link="rr_wheel_link"/> <origin rpy="0.0 0.0 0.0" xyz="-0.053 -0.096 0.0"/> <axis xyz="0.0 1.0 0.0"/> <limit effort="1.5" velocity="24.0"/> <dynamics damping="0.001" friction="0.001"/> </joint> <link name="rr_wheel_link"> <visual> <geometry> <mesh filename="package://rosbot_description/meshes/wheel_b.dae" scale="1.0 1.0 1.0"/> </geometry> <origin rpy="0.0 0.0 0.0" xyz="0.0 0.0 0.0"/> </visual> <collision> <geometry> <cylinder length="0.036" radius="0.0425"/> </geometry> <origin rpy="1.5707963267948966 0.0 0.0" xyz="0.0 0.0 0.0"/> </collision> <inertial> <mass value="0.074"/> <inertia ixx="4.1e-05" ixy="0.0" ixz="0.0" iyy="6.7e-05" iyz="0.0" izz="4.1e-05"/> </inertial> </link> <ros2_control name="imu" type="sensor"> <hardware> <plugin>rosbot_hardware_interfaces/RosbotImuSensor</plugin> <param name="connection_timeout_ms">120000</param> <param name="connection_check_period_ms">500</param> </hardware> <sensor name="imu"> <state_interface name="orientation.x"/> <state_interface name="orientation.y"/> <state_interface name="orientation.z"/> <state_interface name="orientation.w"/> <state_interface name="angular_velocity.x"/> <state_interface name="angular_velocity.y"/> <state_interface name="angular_velocity.z"/> <state_interface name="linear_acceleration.x"/> <state_interface name="linear_acceleration.y"/> <state_interface name="linear_acceleration.z"/> </sensor> </ros2_control> <ros2_control name="wheels" type="system"> <hardware> <plugin>rosbot_hardware_interfaces/RosbotSystem</plugin> <param name="connection_timeout_ms">120000</param> <param name="connection_check_period_ms">500</param> <!-- Firmware from https://github.com/husarion/rosbot_ros2_firmware could not override this names --> <param name="velocity_command_joint_order"> rr_wheel_joint, rl_wheel_joint, fr_wheel_joint, fl_wheel_joint </param> </hardware> <joint name="fl_wheel_joint"> <command_interface name="velocity"/> <state_interface name="position"/> <state_interface name="velocity"/> </joint> <joint name="fr_wheel_joint"> <command_interface name="velocity"/> <state_interface name="position"/> <state_interface name="velocity"/> </joint> <joint name="rl_wheel_joint"> <command_interface name="velocity"/> <state_interface name="position"/> <state_interface name="velocity"/> </joint> <joint name="rr_wheel_joint"> <command_interface name="velocity"/> <state_interface name="position"/> <state_interface name="velocity"/> </joint> </ros2_control> <joint name="cover_to_slamtec_rplidar_a2_joint" type="fixed"> <origin rpy="0.0 0.0 0.0" xyz="0.02 0.0 0.0"/> <parent link="cover_link"/> <child link="slamtec_rplidar_a2_link"/> </joint> <link name="slamtec_rplidar_a2_link"> <visual> <origin rpy="0.0 0.0 0.0" xyz="0.0 0.0 0.0"/> <geometry> <mesh filename="package://ros_components_description/meshes/slamtec_rplidar_ax.dae"/> </geometry> </visual> <collision> <origin rpy="0.0 0.0 0.0" xyz="0.0 0.0 0.0205"/> <geometry> <cylinder length="0.041" radius="0.038"/> </geometry> </collision> <inertial> <origin rpy="0.0 0.0 0.0" xyz="0.0 0.0 0.0205"/> <mass value="0.190"/> <inertia ixx="0.000095206" ixy="0.0" ixz="0.0" iyy="0.000095206" iyz="0.0" izz="0.00013718"/> </inertial> </link> <joint name="slamtec_rplidar_a2_to_laser_joint" type="fixed"> <origin rpy="0.0 0.0 3.141592653589793" xyz="0.0 0.0 0.031"/> <parent link="slamtec_rplidar_a2_link"/> <child link="laser"/> </joint> <link name="laser"/> <gazebo reference="laser"> <sensor name="rplidar_a2_sensor" type="lidar"> <topic>scan</topic> <frame_id>laser</frame_id> <ignition_frame_id>laser</ignition_frame_id> <update_rate>10.0</update_rate> <ray> <scan> <horizontal> <samples>1600</samples> <resolution>1</resolution> <min_angle>-3.141592653589793</min_angle> <max_angle>3.141592653589793</max_angle> </horizontal> </scan> <range> <min>0.2</min> <max>10.0</max> <resolution>0.05</resolution> </range> <noise> <type>gaussian</type> <mean>0.0</mean> <stddev>0.001</stddev> </noise> </ray> <always_on>true</always_on> <visualize>false</visualize> <ros> <namespace></namespace> </ros> </sensor> </gazebo> <joint name="camera_to_camera_orbbec_astra_joint" type="fixed"> <origin rpy="0.0 0.0 0.0" xyz="0.0 0.0 0.0"/> <parent link="camera_link"/> <child link="camera_orbbec_astra_link"/> </joint> <link name="camera_orbbec_astra_link"> <visual> <origin rpy="0.0 0.0 0.0" xyz="0.0 0.0 0.0"/> <geometry> <mesh filename="package://ros_components_description/meshes/orbbec_astra.dae"/> </geometry> </visual> <!-- camera module collision --> <collision> <origin rpy="0.0 0.0 0.0" xyz="0.0024999999999999988 0.0 0.034"/> <geometry> <box size="0.04 0.165 0.03"/> </geometry> </collision> <!-- mounting base model collision --> <collision> <origin rpy="0.0 0.0 0.0" xyz="-0.006499999999999999 0.0 0.0095"/> <geometry> <box size="0.06 0.06 0.019"/> </geometry> </collision> <inertial> <origin rpy="0.0 0.0 0.0" xyz="0.0 0.0 0.028999999999999998"/> <mass value="0.300"/> <inertia ixx="0.00073916" ixy="0.0" ixz="0.0" iyy="0.00015435" iyz="0.0" izz="0.00077395"/> </inertial> </link> <joint name="camera_to_camera_color_joint" type="fixed"> <origin rpy="-0.003 0.0 -0.003" xyz="-0.002 0.0125 0.03325"/> <parent link="camera_link"/> <child link="camera_color_frame"/> </joint> <link name="camera_depth_frame"/> <joint name="camera_to_camera_depth_joint" type="fixed"> <origin rpy="0.0 0.0 0.0" xyz="0.0 0.0 0.03325"/> <parent link="camera_link"/> <child link="camera_depth_frame"/> </joint> <link name="camera_color_frame"/> <joint name="camera_color_to_camera_color_optical_joint" type="fixed"> <origin rpy="-1.5707963267948966 0.0 -1.5707963267948966" xyz="0.0 0.0 0.0"/> <parent link="camera_color_frame"/> <child link="camera_color_optical_frame"/> </joint> <link name="camera_depth_optical_frame"/> <joint name="camera_depth_to_camera_depth_optical_joint" type="fixed"> <origin rpy="-1.5707963267948966 0.0 -1.5707963267948966" xyz="0.0 0.0 0.0"/> <parent link="camera_depth_frame"/> <child link="camera_depth_optical_frame"/> </joint> <link name="camera_color_optical_frame"/> <gazebo reference="camera_orbbec_astra_link"> <!-- https://github.com/orbbec/OrbbecSDK_ROS2#all-available-topics --> <sensor name="camera_orbbec_astra_color" type="camera"> <always_on>true</always_on> <update_rate>30.0</update_rate> <topic>camera/color/image_raw</topic> <visualize>false</visualize> <ignition_frame_id>camera_color_optical_frame</ignition_frame_id> <horizontal_fov>1.0471975511965976</horizontal_fov> <image> <width>640</width> <height>480</height> </image> <clip> <near>0.6</near> <far>8.0</far> </clip> <ros> <namespace></namespace> </ros> </sensor> <sensor name="camera_orbbec_astra_depth" type="depth_camera"> <always_on>true</always_on> <update_rate>10.0</update_rate> <topic>camera/depth/image_raw</topic> <visualize>false</visualize> <ignition_frame_id>camera_depth_optical_frame</ignition_frame_id> <camera> <horizontal_fov>1.0471975511965976</horizontal_fov> <image> <width>640</width> <height>480</height> </image> <clip> <near>0.6</near> <far>8.0</far> </clip> <noise> <type>gaussian</type> <mean>0.0</mean> <stddev>0.005</stddev> </noise> </camera> <ros> <namespace></namespace> </ros> </sensor> </gazebo> </robot>
